<?xml version="1.0"?>
<robot name="wearable_hand">

  <link name="world"/>

  <link name="elbow_roll_link">
    <inertial>
      <mass value="0.01"/>
      <inertia ixx="0.001" ixy="0" ixz="0" iyy="0.001" iyz="0" izz="0.001"/>
    </inertial>
  </link>

  <joint name="elbow_roll_joint" type="revolute">
    <parent link="world"/>
    <child link="elbow_roll_link"/>
    <origin xyz="0 0 1.0" rpy="0 0 0"/> 
    <axis xyz="1 0 0"/>
    <limit lower="-1.57" upper="1.57" effort="10" velocity="1.0"/>
  </joint>

  <link name="elbow_pitch_link">
    <inertial>
      <mass value="0.01"/>
      <inertia ixx="0.001" ixy="0" ixz="0" iyy="0.001" iyz="0" izz="0.001"/>
    </inertial>
  </link>

  <joint name="elbow_pitch_joint" type="revolute">
    <parent link="elbow_roll_link"/>
    <child link="elbow_pitch_link"/>
    <origin xyz="0 0 0" rpy="0 0 0"/>
    <axis xyz="0 1 0"/>
    <limit lower="-1.57" upper="1.57" effort="10" velocity="1.0"/>
  </joint>

  <joint name="elbow_yaw_joint" type="revolute">
    <parent link="elbow_pitch_link"/>
    <child link="forearm_link"/> 
    <origin xyz="0 0 0" rpy="0 0 0"/>
    <axis xyz="0 0 1"/>
    <limit lower="-1.57" upper="1.57" effort="10" velocity="1.0"/>
  </joint>

  <link name="forearm_link">
    <visual>
      <geometry>
        <box size="0.1 0.1 0.3"/> 
      </geometry>
      <origin xyz="0 0 0.15" rpy="0 0 0"/> 
      <material name="gray">
        <color rgba="0.5 0.5 0.5 1"/>
      </material>
    </visual>
    <inertial>
      <mass value="1.0"/>
      <inertia ixx="0.01" ixy="0" ixz="0" iyy="0.01" iyz="0" izz="0.01"/>
    </inertial>
  </link>

  <link name="imu_brachioradialis">
    <visual>
      <geometry>
        <sphere radius="0.015"/> 
      </geometry>
      <material name="red">
        <color rgba="1 0 0 1"/> </material>
    </visual>
  </link>

  <joint name="fixed_brachio" type="fixed">
    <parent link="forearm_link"/>
    <child link="imu_brachioradialis"/>
    <origin xyz="0.05 0 0.1" rpy="0 0 0"/> 
  </joint>

  <link name="imu_wrist_sensor">
    <visual>
      <geometry>
        <sphere radius="0.015"/>
      </geometry>
      <material name="blue">
        <color rgba="0 0 1 1"/> </material>
    </visual>
  </link>

  <joint name="fixed_wrist" type="fixed">
    <parent link="forearm_link"/>
    <child link="imu_wrist_sensor"/>
    <origin xyz="0 0 0.28" rpy="0 0 0"/> 
  </joint>

  <link name="hand_link">
    <visual>
      <geometry>
        <box size="0.08 0.1 0.02"/> 
      </geometry>
      <material name="skin">
        <color rgba="0.8 0.6 0.4 1"/> </material>
    </visual>
    <inertial>
      <mass value="0.1"/>
      <inertia ixx="0.001" ixy="0" ixz="0" iyy="0.001" iyz="0" izz="0.001"/>
    </inertial>
  </link>

  <joint name="wrist_fixed" type="fixed"> 
    <parent link="forearm_link"/>
    <child link="hand_link"/>
    <origin xyz="0 0 0.31" rpy="0 0 0"/>
  </joint>

  <link name="index_finger_link">
    <visual>
      <geometry>
        <cylinder length="0.08" radius="0.008"/> </geometry>
      <material name="skin"/>
    </visual>
    <inertial>
      <mass value="0.05"/>
      <inertia ixx="0.0001" ixy="0" ixz="0" iyy="0.0001" iyz="0" izz="0.0001"/>
    </inertial>
  </link>

  <joint name="index_finger_joint" type="revolute">
    <parent link="hand_link"/>
    <child link="index_finger_link"/>
    <origin xyz="0 0.03 0.04" rpy="0 0 0"/>
    <axis xyz="1 0 0"/> <limit lower="0.0" upper="1.57" effort="1.0" velocity="1.0"/>
  </joint>

  <gazebo>
    <plugin filename="gz-sim-joint-state-publisher-system"
            name="gz::sim::systems::JointStatePublisher">
      <topic>joint_states</topic> <joint_name>elbow_roll_joint</joint_name>
      <joint_name>elbow_pitch_joint</joint_name>
      <joint_name>elbow_yaw_joint</joint_name>
      <joint_name>index_finger_joint</joint_name>
    </plugin>

    <plugin filename="gz-sim-apply-joint-force-system"
            name="gz::sim::systems::ApplyJointForce">
      <joint_name>elbow_roll_joint</joint_name>
    </plugin>
    <plugin filename="gz-sim-apply-joint-force-system"
            name="gz::sim::systems::ApplyJointForce">
      <joint_name>elbow_pitch_joint</joint_name>
    </plugin>
    <plugin filename="gz-sim-apply-joint-force-system"
            name="gz::sim::systems::ApplyJointForce">
      <joint_name>elbow_yaw_joint</joint_name>
    </plugin>
    <plugin filename="gz-sim-apply-joint-force-system"
            name="gz::sim::systems::ApplyJointForce">
      <joint_name>index_finger_joint</joint_name>
    </plugin>
  </gazebo>

</robot>